{
 "cells": [
  {
   "cell_type": "markdown",
   "id": "e9c4046e",
   "metadata": {},
   "source": [
    "https://chat.openai.com/share/fcd5c898-e284-4a8f-a623-b481173b9660"
   ]
  },
  {
   "cell_type": "code",
   "execution_count": 1,
   "id": "9584dff6",
   "metadata": {},
   "outputs": [
    {
     "ename": "IndentationError",
     "evalue": "expected an indented block (46875012.py, line 5)",
     "output_type": "error",
     "traceback": [
      "\u001b[1;36m  File \u001b[1;32m\"C:\\Users\\ronan\\AppData\\Local\\Temp\\ipykernel_832\\46875012.py\"\u001b[1;36m, line \u001b[1;32m5\u001b[0m\n\u001b[1;33m    except ExceptionType:\u001b[0m\n\u001b[1;37m    ^\u001b[0m\n\u001b[1;31mIndentationError\u001b[0m\u001b[1;31m:\u001b[0m expected an indented block\n"
     ]
    }
   ],
   "source": [
    "try:\n",
    "    # Code block where an exception might occur\n",
    "    # You should put the code that might raise an exception inside this block\n",
    "    # If an exception occurs, it will be caught by the corresponding except block\n",
    "except ExceptionType:\n",
    "    # Code block to handle the exception\n",
    "    # This block will execute when an exception of type ExceptionType occurs\n"
   ]
  },
  {
   "cell_type": "code",
   "execution_count": 5,
   "id": "b47ca58b",
   "metadata": {},
   "outputs": [
    {
     "name": "stdout",
     "output_type": "stream",
     "text": [
      "Enter a number: 0\n",
      "Error: Cannot divide by zero.\n"
     ]
    }
   ],
   "source": [
    "try:\n",
    "    num = int(input(\"Enter a number: \"))\n",
    "    result = 10 / num\n",
    "    print(\"Result:\", result)\n",
    "except ZeroDivisionError:\n",
    "    print(\"Error: Cannot divide by zero.\")\n",
    "except ValueError:\n",
    "    print(\"Error: Invalid input. Please enter a valid integer.\")\n"
   ]
  },
  {
   "cell_type": "code",
   "execution_count": 10,
   "id": "8f123aab",
   "metadata": {},
   "outputs": [
    {
     "name": "stdout",
     "output_type": "stream",
     "text": [
      "Enter a number: 0\n",
      "Error: Invalid input or cannot divide by zero.\n"
     ]
    }
   ],
   "source": [
    "try:\n",
    "    num = int(input(\"Enter a number: \"))\n",
    "    result = 1 / num\n",
    "    print(\"Reciprocal is:\", result)\n",
    "except (ZeroDivisionError, ValueError):\n",
    "    print(\"Error: Invalid input or cannot divide by zero.\")\n",
    "\n"
   ]
  },
  {
   "cell_type": "code",
   "execution_count": 11,
   "id": "afa0dbeb",
   "metadata": {},
   "outputs": [
    {
     "name": "stdout",
     "output_type": "stream",
     "text": [
      "Enter a number: we\n",
      "An error occurred: invalid literal for int() with base 10: 'we'\n"
     ]
    }
   ],
   "source": [
    "try:\n",
    "    num = int(input(\"Enter a number: \"))\n",
    "    result = 10 / num\n",
    "    print(\"Result:\", result)\n",
    "except Exception as e:\n",
    "    print(\"An error occurred:\", e)\n"
   ]
  },
  {
   "cell_type": "code",
   "execution_count": 13,
   "id": "4eb4b150",
   "metadata": {},
   "outputs": [
    {
     "name": "stdout",
     "output_type": "stream",
     "text": [
      "Enter a number: 2\n",
      "Reciprocal: 0.5\n",
      "End of the program.\n"
     ]
    }
   ],
   "source": [
    "try:\n",
    "    num = int(input(\"Enter a number: \"))\n",
    "    result = 1 / num\n",
    "except ZeroDivisionError:\n",
    "    print(\"Error: Cannot divide by zero.\")\n",
    "except ValueError:\n",
    "    print(\"Error: Invalid input. Please enter a valid integer.\")\n",
    "else:\n",
    "    print(\"Reciprocal:\", result)\n",
    "finally:\n",
    "    print(\"End of the program.\")\n"
   ]
  },
  {
   "cell_type": "code",
   "execution_count": null,
   "id": "7e6056bc",
   "metadata": {},
   "outputs": [],
   "source": []
  },
  {
   "cell_type": "markdown",
   "id": "8974f052",
   "metadata": {},
   "source": [
    "In Python, a \"try-except\" block is used for handling exceptions, which are errors that occur during the execution of a program. When certain operations in Python encounter an error, they raise an exception, and if the exception is not handled, the program will terminate with an error message. To prevent this, you can use a try-except block to catch and handle exceptions gracefully.\n",
    "\n",
    "The basic syntax of a try-except block in Python is as follows:\n",
    "\n",
    "```python\n",
    "try:\n",
    "    # Code block where an exception might occur\n",
    "    # You should put the code that might raise an exception inside this block\n",
    "    # If an exception occurs, it will be caught by the corresponding except block\n",
    "except ExceptionType:\n",
    "    # Code block to handle the exception\n",
    "    # This block will execute when an exception of type ExceptionType occurs\n",
    "```\n",
    "\n",
    "Here's how the try-except block works:\n",
    "\n",
    "1. The code inside the \"try\" block is executed.\n",
    "2. If no exception occurs, the \"try\" block runs without any interruption, and the \"except\" block is skipped.\n",
    "3. If an exception occurs during the execution of the \"try\" block, Python immediately jumps to the corresponding \"except\" block (if one exists) based on the type of the exception raised.\n",
    "4. The \"except\" block handles the exception, allowing you to take appropriate actions, log errors, or display user-friendly error messages, preventing the program from crashing.\n",
    "\n",
    "Let's look at a few examples to understand how try-except blocks work:\n",
    "\n",
    "Example 1 - Handling a specific exception:\n",
    "\n",
    "```python\n",
    "try:\n",
    "    num = int(input(\"Enter a number: \"))\n",
    "    result = 10 / num\n",
    "    print(\"Result:\", result)\n",
    "except ZeroDivisionError:\n",
    "    print(\"Error: Cannot divide by zero.\")\n",
    "except ValueError:\n",
    "    print(\"Error: Invalid input. Please enter a valid integer.\")\n",
    "```\n",
    "\n",
    "In this example, the user is asked to input a number. If the user enters \"0\" as the input, a `ZeroDivisionError` will be raised because dividing by zero is not allowed. If the user enters something that cannot be converted to an integer, a `ValueError` will be raised. The respective except blocks will handle these specific exceptions.\n",
    "\n",
    "Example 2 - Handling multiple exceptions with a single except block:\n",
    "\n",
    "```python\n",
    "try:\n",
    "    num = int(input(\"Enter a number: \"))\n",
    "    result = 10 / num\n",
    "    print(\"Result:\", result)\n",
    "except (ZeroDivisionError, ValueError):\n",
    "    print(\"Error: Invalid input or cannot divide by zero.\")\n",
    "```\n",
    "\n",
    "In this example, we use a single `except` block to handle multiple exceptions (`ZeroDivisionError` and `ValueError`) with the same error message.\n",
    "\n",
    "Example 3 - Handling all exceptions:\n",
    "\n",
    "```python\n",
    "try:\n",
    "    num = int(input(\"Enter a number: \"))\n",
    "    result = 10 / num\n",
    "    print(\"Result:\", result)\n",
    "except Exception as e:\n",
    "    print(\"An error occurred:\", e)\n",
    "```\n",
    "\n",
    "In this example, the `except` block catches any exception that inherits from the `Exception` class (which includes almost all exceptions in Python). The `as e` part allows you to access the exception object for further examination or logging.\n",
    "\n",
    "Remember that it is generally a good practice to catch specific exceptions whenever possible instead of using a broad `except` block that catches all exceptions. This helps you handle errors more precisely and makes your code more maintainable.\n",
    "\n",
    "Additionally, you can use an optional `else` block after the `except` block, which runs if no exception occurs in the `try` block. There's also a `finally` block, which is executed regardless of whether an exception occurred or not. The `finally` block is typically used for cleanup actions that must be performed, such as closing files or releasing resources.\n",
    "\n",
    "Example with `else` and `finally` blocks:\n",
    "\n",
    "```python\n",
    "try:\n",
    "    num = int(input(\"Enter a number: \"))\n",
    "    result = 10 / num\n",
    "except ZeroDivisionError:\n",
    "    print(\"Error: Cannot divide by zero.\")\n",
    "except ValueError:\n",
    "    print(\"Error: Invalid input. Please enter a valid integer.\")\n",
    "else:\n",
    "    print(\"Result:\", result)\n",
    "finally:\n",
    "    print(\"End of the program.\")\n",
    "```\n",
    "\n",
    "In summary, the try-except block is a powerful tool for handling exceptions and providing more robust error-handling in your Python programs. It helps prevent unexpected crashes and improves the overall user experience by gracefully handling errors."
   ]
  }
 ],
 "metadata": {
  "kernelspec": {
   "display_name": "Python 3 (ipykernel)",
   "language": "python",
   "name": "python3"
  },
  "language_info": {
   "codemirror_mode": {
    "name": "ipython",
    "version": 3
   },
   "file_extension": ".py",
   "mimetype": "text/x-python",
   "name": "python",
   "nbconvert_exporter": "python",
   "pygments_lexer": "ipython3",
   "version": "3.9.13"
  },
  "toc": {
   "base_numbering": 1,
   "nav_menu": {},
   "number_sections": true,
   "sideBar": true,
   "skip_h1_title": true,
   "title_cell": "Table of Contents",
   "title_sidebar": "Contents",
   "toc_cell": false,
   "toc_position": {},
   "toc_section_display": true,
   "toc_window_display": true
  }
 },
 "nbformat": 4,
 "nbformat_minor": 5
}
